<?xml version="1.0" encoding="UTF-8"?>
<!-- Generated by org.testng.reporters.JUnitXMLReporter -->
<testsuite hostname="WIN7P4A-0081" name="Default test" tests="1" failures="1" timestamp="3 Jul 2017 06:43:18 GMT" time="18.443" errors="0">
  <testcase name="testRunner" time="18.342" classname="testscripts.LoginScenario.TestForMarineValidLogin">
    <failure type="java.lang.AssertionError" message="The test case &amp;quot;TestForMarineValidLogin&amp;quot;is not found in the test data sheet &amp;quot;General_Data&amp;quot;!">
      <![CDATA[java.lang.AssertionError: The test case "TestForMarineValidLogin"is not found in the test data sheet "General_Data"!
	at org.testng.Assert.fail(Assert.java:94)
	at com.cognizant.Craft.CRAFTTestCase.tearDownTestRunner(CRAFTTestCase.java:105)
	at testscripts.LoginScenario.TestForMarineValidLogin.testRunner(TestForMarineValidLogin.java:37)
	at sun.reflect.NativeMethodAccessorImpl.invoke0(Native Method)
	at sun.reflect.NativeMethodAccessorImpl.invoke(Unknown Source)
	at sun.reflect.DelegatingMethodAccessorImpl.invoke(Unknown Source)
	at java.lang.reflect.Method.invoke(Unknown Source)
	at org.testng.internal.MethodInvocationHelper.invokeMethod(MethodInvocationHelper.java:86)
	at org.testng.internal.Invoker.invokeMethod(Invoker.java:643)
	at org.testng.internal.Invoker.invokeTestMethod(Invoker.java:820)
	at org.testng.internal.TestMethodWithDataProviderMethodWorker.call(TestMethodWithDataProviderMethodWorker.java:75)
	at org.testng.internal.TestMethodWithDataProviderMethodWorker.call(TestMethodWithDataProviderMethodWorker.java:14)
	at java.util.concurrent.FutureTask.run(Unknown Source)
	at java.util.concurrent.Executors$RunnableAdapter.call(Unknown Source)
	at java.util.concurrent.FutureTask.run(Unknown Source)
	at java.util.concurrent.ThreadPoolExecutor.runWorker(Unknown Source)
	at java.util.concurrent.ThreadPoolExecutor$Worker.run(Unknown Source)
	at java.lang.Thread.run(Unknown Source)
]]>
    </failure>
  </testcase> <!-- testRunner -->
</testsuite> <!-- Default test -->
